<?xml version="1.0" encoding="UTF-8"?>
<!-- Generated by org.testng.reporters.JUnitReportReporter -->
<testsuite skipped="3" hostname="APERGHN1UG" name="org.practice.Manualfailrun" tests="7" failures="1" timestamp="14 Feb 2021 00:56:19 GMT" time="0.086" errors="0">
  <testcase name="tc222" time="0.003" classname="org.practice.Manualfailrun">
    <skipped/>
  </testcase> <!-- tc222 -->
  <testcase name="tc222" time="0.006" classname="org.practice.Manualfailrun">
    <skipped/>
  </testcase> <!-- tc222 -->
  <testcase name="tc222" time="0.032" classname="org.practice.Manualfailrun">
    <skipped/>
  </testcase> <!-- tc222 -->
  <testcase name="tc111" time="0.029" classname="org.practice.Manualfailrun"/>
  <testcase name="tc333" time="0.012" classname="org.practice.Manualfailrun"/>
  <testcase name="tc222" time="0.002" classname="org.practice.Manualfailrun">
    <failure type="java.lang.AssertionError" message="test case failed expected [true] but found [false]">
      <![CDATA[java.lang.AssertionError: test case failed expected [true] but found [false]
at org.testng.Assert.fail(Assert.java:96)
at org.testng.Assert.failNotEquals(Assert.java:776)
at org.testng.Assert.assertTrue(Assert.java:44)
at org.practice.Manualfailrun.tc222(Manualfailrun.java:17)
at sun.reflect.NativeMethodAccessorImpl.invoke0(Native Method)
at sun.reflect.NativeMethodAccessorImpl.invoke(Unknown Source)
at sun.reflect.DelegatingMethodAccessorImpl.invoke(Unknown Source)
at java.lang.reflect.Method.invoke(Unknown Source)
at org.testng.internal.MethodInvocationHelper.invokeMethod(MethodInvocationHelper.java:124)
at org.testng.internal.Invoker.invokeMethod(Invoker.java:583)
at org.testng.internal.Invoker.retryFailed(Invoker.java:839)
at org.testng.internal.Invoker.invokeTestMethods(Invoker.java:1010)
at org.testng.internal.TestMethodWorker.invokeTestMethods(TestMethodWorker.java:125)
at org.testng.internal.TestMethodWorker.run(TestMethodWorker.java:109)
at org.testng.TestRunner.privateRun(TestRunner.java:648)
at org.testng.TestRunner.run(TestRunner.java:505)
at org.testng.SuiteRunner.runTest(SuiteRunner.java:455)
at org.testng.SuiteRunner.runSequentially(SuiteRunner.java:450)
at org.testng.SuiteRunner.privateRun(SuiteRunner.java:415)
at org.testng.SuiteRunner.run(SuiteRunner.java:364)
at org.testng.SuiteRunnerWorker.runSuite(SuiteRunnerWorker.java:52)
at org.testng.SuiteRunnerWorker.run(SuiteRunnerWorker.java:84)
at org.testng.TestNG.runSuitesSequentially(TestNG.java:1208)
at org.testng.TestNG.runSuitesLocally(TestNG.java:1137)
at org.testng.TestNG.runSuites(TestNG.java:1049)
at org.testng.TestNG.run(TestNG.java:1017)
at org.testng.remote.AbstractRemoteTestNG.run(AbstractRemoteTestNG.java:114)
at org.testng.remote.RemoteTestNG.initAndRun(RemoteTestNG.java:251)
at org.testng.remote.RemoteTestNG.main(RemoteTestNG.java:77)
]]>
    </failure>
  </testcase> <!-- tc222 -->
  <testcase name="tc444" time="0.002" classname="org.practice.Manualfailrun"/>
</testsuite> <!-- org.practice.Manualfailrun -->
